Workbook

Sheet READ ME
A1: India Labor Arbitrage Program — Monthly Consolidation Workbook
A3: PURPOSE
A4: Single consolidation file for the India GCC ramp-up program. Each org finance partner updates their own Org tab monthly; the Consolidation and Dashboard tabs roll up automatically.
A6: HOW TO SET UP (owner, one time)
A7: 1. Go to the Setup tab and replace 'Org 1 — REPLACE' etc. with the real organization names. Every tab picks the names up automatically.
A8: 2. Optionally rename the Org_1..Org_8 sheet tabs to match — Excel updates all formulas automatically when a sheet is renamed.
A9: 3. Replace the ILLUSTRATIVE placeholder numbers on the Targets tab with the committed monthly baseline you distributed to each org (yellow cells).
A10: 4. Org_1 contains EXAMPLE actuals for Jan–Mar 2026 to demonstrate the mechanics — clear them before first use.
A12: HOW TO SUBMIT (org finance partners, monthly)
A13: 1. Open your org's tab. Enter values in BLUE cells only for the month just closed.
A14: 2. GREEN cells are filled centrally from PlanIt/HR — do not overwrite unless asked.
A15: 3. GREY cells are your committed targets, linked from the Targets tab — never edit on this tab.
... A28: BLUE = org enters data | GREEN = central fill (PlanIt/HR) | GREY = linked target (do not edit) | YELLOW = placeholder to replace during setup

Sheet Setup
A1: Setup — organization names and lists
A3: REPLACE the names below with your 8 organizations. All tabs reference these cells.
A4: Org tab Org_1 display name: | B4: Org 1 — REPLACE
A5: Org tab Org_2 display name: | B5: Org 2 — REPLACE
A6: Org tab Org_3 display name: | B6: Org 3 — REPLACE
A7: Org tab Org_4 display name: | B7: Org 4 — REPLACE
A8: Org tab Org_5 display name: | B8: Org 5 — REPLACE
A9: Org tab Org_6 display name: | B9: Org 6 — REPLACE
A10: Org tab Org_7 display name: | B10: Org 7 — REPLACE
A11: Org tab Org_8 display name: | B11: Org 8 — REPLACE
A13: Dropdown lists (used by data validation):
A14: RAG: | B14: Green
B15: Amber
B16: Red
A18: Yes/No: | B18: Y
B19: N

Sheet Targets
A1: Committed monthly baseline by organization
A2: ILLUSTRATIVE PLACEHOLDERS — replace every yellow cell with the committed baseline distributed to the orgs. Baseline changes only via approved change request.
C4: 2026 | O4: 2027 | AA4: 2028 | AM4: 2029
A5: Metric | B5: Unit / who fills | C5: 46023 | D5: 46054 | E5: 46082 | F5: 46113 | G5: 46143 | H5: 46174 | I5: 46204 | J5: 46235 | K5: 46266 | L5: 46296 | M5: 46327 | N5: 46357 | O5: 46388 | P5: 46419 | Q5: 46447 | R5: 46478 | S5: 46508 | T5: 46539 | U5: 46569 | V5: 46600 | W5: 46631 | X5: 46661 | Y5: 46692 | Z5: 46722 | AA5: 46753 | AB5: 46784 | AC5: 46813 | AD5: 46844 | AE5: 46874 | AF5: 46905 | AG5: 46935 | AH5: 46966 | AI5: 46997 | AJ5: 47027 | AK5: 47058 | AL5: 47088 | AM5: 47119 | AN5: 47150 | AO5: 47178 | AP5: 47209 | AQ5: 47239 | AR5: 47270 | AS5: 47300 | AT5: 47331 | AU5: 47362 | AV5: 47392 | AW5: 47423 | AX5: 47453
A7: =CONCATENATE("ORG: ",Setup!$B$4)
A8: India hires (heads) | C8: 9 | D8: 9 | E8: 9 | F8: 9 | G8: 9 | H8: 9 | I8: 9 | J8: 9 | K8: 9 | L8: 9 | M8: 9 | N8: 9 | O8: 15 | P8: 15 | Q8: 15 | R8: 15 | S8: 15 | T8: 15 | U8: 15 | V8: 15 | W8: 15 | X8: 15 | Y8: 15 | Z8: 15 | AA8: 0 | AB8: 0 | AC8: 0 | AD8: 0 | AE8: 0 | AF8: 0 | AG8: 0 | AH8: 0 | AI8: 0 | AJ8: 0 | AK8: 0 | AL8: 0 | AM8: 0 | AN8: 0 | AO8: 0 | AP8: 0 | AQ8: 0 | AR8: 0 | AS8: 0 | AT8: 0 | AU8: 0 | AV8: 0 | AW8: 0 | AX8: 0
A9: Reductions — Professional services ($K) | C9: 0 | D9: 0 | E9: 0 | F9: 0 | G9: 38 | H9: 75 | I9: 112 | J9: 150 | K9: 188 | L9: 225 | M9: 262 | N9: 300 | O9: 338 | P9: 375 | Q9: 412 | R9: 450 | S9: 488 | T9: 525 | U9: 562 | V9: 600 | W9: 638 | X9: 675 | Y9: 712 | Z9: 750 | AA9: 788 | AB9: 825 | AC9: 862 | AD9: 900 | AE9: 900 | AF9: 900 | AG9: 900 | AH9: 900 | AI9: 900 | AJ9: 900 | AK9: 900 | AL9: 900 | AM9: 900 | AN9: 900 | AO9: 900 | AP9: 900 | AQ9: 900 | AR9: 900 | AS9: 900 | AT9: 900 | AU9: 900 | AV9: 900 | AW9: 900 | AX9: 900
A10: Reductions — Offshore contractors ($K) | C10: 0 | D10: 0 | E10: 0 | F10: 0 | G10: 0 | H10: 0 | I10: 0 | J10: 15 | K10: 30 | L10: 45 | M10: 60 | N10: 75 | O10: 90 | P10: 105 | Q10: 120 | R10: 135 | S10: 150 | T10: 165 | U10: 180 | V10: 195 | W10: 210 | X10: 225 | Y10: 240 | Z10: 255 | AA10: 270 | AB10: 285 | AC10: 300 | AD10: 315 | AE10: 330 | AF10: 345 | AG10: 360 | AH10: 375 | AI10: 375 | AJ10: 375 | AK10: 375 | AL10: 375 | AM10: 375 | AN10: 375 | AO10: 375 | AP10: 375 | AQ10: 375 | AR10: 375 | AS10: 375 | AT10: 375 | AU10: 375 | AV10: 375 | AW10: 375 | AX10: 375
A11: Reductions — Onshore contractors ($K) | C11: 0 | D11: 0 | E11: 0 | F11: 0 | G11: 0 | H11: 0 | I11: 0 | J11: 12 | K11: 24 | L11: 36 | M11: 48 | N11: 60 | O11: 72 | P11: 84 | Q11: 96 | R11: 108 | S11: 120 | T11: 132 | U11: 144 | V11: 156 | W11: 168 | X11: 180 | Y11: 192 | Z11: 204 | AA11: 216 | AB11: 228 | AC11: 240 | AD11: 252 | AE11: 264 | AF11: 276 | AG11: 288 | AH11: 300 | AI11: 300 | AJ11: 300 | AK11: 300 | AL11: 300 | AM11: 300 | AN11: 300 | AO11: 300 | AP11: 300 | AQ11: 300 | AR11: 300 | AS11: 300 | AT11: 300 | AU11: 300 | AV11: 300 | AW11: 300 | AX11: 300
A12: Reductions — Employees / Other ($K) | C12: 0 | D12: 0 | E12: 0 | F12: 0 | G12: 0 | H12: 0 | I12: 0 | J12: 0 | K12: 0 | L12: 0 | M12: 6 | N12: 12 | O12: 18 | P12: 24 | Q12: 30 | R12: 36 | S12: 42 | T12: 48 | U12: 54 | V12: 60 | W12: 66 | X12: 72 | Y12: 78 | Z12: 84 | AA12: 90 | AB12: 96 | AC12: 102 | AD12: 108 | AE12: 114 | AF12: 120 | AG12: 126 | AH12: 132 | AI12: 138 | AJ12: 144 | AK12: 150 | AL12: 150 | AM12: 150 | AN12: 150 | AO12: 150 | AP12: 150 | AQ12: 150 | AR12: 150 | AS12: 150 | AT12: 150 | AU12: 150 | AV12: 150 | AW12: 150 | AX12: 150
A13: India cost adds ($K) | C13: 34 | D13: 68 | E13: 101 | F13: 135 | G13: 169 | H13: 202 | I13: 236 | J13: 270 | K13: 304 | L13: 338 | M13: 371 | N13: 405 | O13: 461 | P13: 518 | Q13: 574 | R13: 630 | S13: 686 | T13: 742 | U13: 799 | V13: 855 | W13: 911 | X13: 968 | Y13: 1024 | Z13: 1080 | AA13: 1080 | AB13: 1080 | AC13: 1080 | AD13: 1080 | AE13: 1080 | AF13: 1080 | AG13: 1080 | AH13: 1080 | AI13: 1080 | AJ13: 1080 | AK13: 1080 | AL13: 1080 | AM13: 1080 | AN13: 1080 | AO13: 1080 | AP13: 1080 | AQ13: 1080 | AR13: 1080 | AS13: 1080 | AT13: 1080 | AU13: 1080 | AV13: 1080 | AW13: 1080 | AX13: 1080
A14: Net labor arbitrage ($K) | C14: =SUM(C9:C12)-C13 | D14: =SUM(D9:D12)-D13 | E14: =SUM(E9:E12)-E13 | F14: =SUM(F9:F12)-F13 | G14: =SUM(G9:G12)-G13 | H14: =SUM(H9:H12)-H13 | I14: =SUM(I9:I12)-I13 | J14: =SUM(J9:J12)-J13 | ... AX14: =SUM(AX9:AX12)-AX13
A16: =CONCATENATE("ORG: ",Setup!$B$5)
A17: India hires (heads) | C17: 8 | D17: 8 | E17: 8 | F17: 8 | G17: 8 | H17: 8 | I17: 8 | J17: 8 | K17: 8 | L17: 8 | M17: 8 | N17: 8 | O17: 13 | P17: 13 | Q17: 13 | R17: 13 | S17: 13 | T17: 13 | U17: 13 | V17: 13 | W17: 13 | X17: 13 | Y17: 13 | Z17: 13 | AA17: 0 | AB17: 0 | AC17: 0 | AD17: 0 | AE17: 0 | AF17: 0 | AG17: 0 | AH17: 0 | AI17: 0 | AJ17: 0 | AK17: 0 | AL17: 0 | AM17: 0 | AN17: 0 | AO17: 0 | AP17: 0 | AQ17: 0 | AR17: 0 | AS17: 0 | AT17: 0 | AU17: 0 | AV17: 0 | AW17: 0 | AX17: 0
A18: Reductions — Professional services ($K) | C18: 0 | D18: 0 | E18: 0 | F18: 0 | G18: 32 | H18: 65 | I18: 98 | J18: 130 | K18: 162 | L18: 195 | M18: 228 | N18: 260 | O18: 292 | P18: 325 | Q18: 358 | R18: 390 | S18: 422 | T18: 455 | U18: 488 | V18: 520 | W18: 552 | X18: 585 | Y18: 618 | Z18: 650 | AA18: 682 | AB18: 715 | AC18: 748 | AD18: 780 | AE18: 780 | AF18: 780 | AG18: 780 | AH18: 780 | AI18: 780 | AJ18: 780 | AK18: 780 | AL18: 780 | AM18: 780 | AN18: 780 | AO18: 780 | AP18: 780 | AQ18: 780 | AR18: 780 | AS18: 780 | AT18: 780 | AU18: 780 | AV18: 780 | AW18: 780 | AX18: 780
A19: Reductions — Offshore contractors ($K) | C19: 0 | D19: 0 | E19: 0 | F19: 0 | G19: 0 | H19: 0 | I19: 0 | J19: 13 | K19: 26 | L19: 39 | M19: 52 | N19: 65 | O19: 78 | P19: 91 | Q19: 104 | R19: 117 | S19: 130 | T19: 143 | U19: 156 | V19: 169 | W19: 182 | X19: 195 | Y19: 208 | Z19: 221 | AA19: 234 | AB19: 247 | AC19: 260 | AD19: 273 | AE19: 286 | AF19: 299 | AG19: 312 | AH19: 325 | AI19: 325 | AJ19: 325 | AK19: 325 | AL19: 325 | AM19: 325 | AN19: 325 | AO19: 325 | AP19: 325 | AQ19: 325 | AR19: 325 | AS19: 325 | AT19: 325 | AU19: 325 | AV19: 325 | AW19: 325 | AX19: 325
A20: Reductions — Onshore contractors ($K) | C20: 0 | D20: 0 | E20: 0 | F20: 0 | G20: 0 | H20: 0 | I20: 0 | J20: 10 | K20: 21 | L20: 31 | M20: 42 | N20: 52 | O20: 62 | P20: 73 | Q20: 83 | R20: 94 | S20: 104 | T20: 114 | U20: 125 | V20: 135 | W20: 146 | X20: 156 | Y20: 166 | Z20: 177 | AA20: 187 | AB20: 198 | AC20: 208 | AD20: 218 | AE20: 229 | AF20: 239 | AG20: 250 | AH20: 260 | AI20: 260 | AJ20: 260 | AK20: 260 | AL20: 260 | AM20: 260 | AN20: 260 | AO20: 260 | AP20: 260 | AQ20: 260 | AR20: 260 | AS20: 260 | AT20: 260 | AU20: 260 | AV20: 260 | AW20: 260 | AX20: 260
A21: Reductions — Employees / Other ($K) | C21: 0 | D21: 0 | E21: 0 | F21: 0 | G21: 0 | H21: 0 | I21: 0 | J21: 0 | K21: 0 | L21: 0 | M21: 5 | N21: 10 | O21: 16 | P21: 21 | Q21: 26 | R21: 31 | S21: 36 | T21: 42 | U21: 47 | V21: 52 | W21: 57 | X21: 62 | Y21: 68 | Z21: 73 | AA21: 78 | AB21: 83 | AC21: 88 | AD21: 94 | AE21: 99 | AF21: 104 | AG21: 109 | AH21: 114 | AI21: 120 | AJ21: 125 | AK21: 130 | AL21: 130 | AM21: 130 | AN21: 130 | AO21: 130 | AP21: 130 | AQ21: 130 | AR21: 130 | AS21: 130 | AT21: 130 | AU21: 130 | AV21: 130 | AW21: 130 | AX21: 130
A22: India cost adds ($K) | C22: 30 | D22: 60 | E22: 90 | F22: 120 | G22: 150 | H22: 180 | I22: 210 | J22: 240 | K22: 270 | L22: 300 | M22: 330 | N22: 360 | O22: 409 | P22: 458 | Q22: 506 | R22: 555 | S22: 604 | T22: 652 | U22: 701 | V22: 750 | W22: 799 | X22: 848 | Y22: 896 | Z22: 945 | AA22: 945 | AB22: 945 | AC22: 945 | AD22: 945 | AE22: 945 | AF22: 945 | AG22: 945 | AH22: 945 | AI22: 945 | AJ22: 945 | AK22: 945 | AL22: 945 | AM22: 945 | AN22: 945 | AO22: 945 | AP22: 945 | AQ22: 945 | AR22: 945 | AS22: 945 | AT22: 945 | AU22: 945 | AV22: 945 | AW22: 945 | AX22: 945
A23: Net labor arbitrage ($K) | C23: =SUM(C18:C21)-C22 | D23: =SUM(D18:D21)-D22 | E23: =SUM(E18:E21)-E22 | F23: =SUM(F18:F21)-F22 | G23: =SUM(G18:G21)-G22 | H23: =SUM(H18:H21)-H22 | I23: =SUM(I18:I21)-I22 | J23: =SUM(J18:J21)-J22 | ... AX23: =SUM(AX18:AX21)-AX22
A25: =CONCATENATE("ORG: ",Setup!$B$6)
A26: India hires (heads) | C26: 7 | D26: 7 | E26: 7 | F26: 7 | G26: 7 | H26: 7 | I26: 7 | J26: 7 | K26: 7 | L26: 7 | M26: 7 | N26: 7 | O26: 12 | P26: 12 | Q26: 12 | R26: 12 | S26: 12 | T26: 12 | U26: 12 | V26: 12 | W26: 12 | X26: 12 | Y26: 12 | Z26: 12 | AA26: 0 | AB26: 0 | AC26: 0 | AD26: 0 | AE26: 0 | AF26: 0 | AG26: 0 | AH26: 0 | AI26: 0 | AJ26: 0 | AK26: 0 | AL26: 0 | AM26: 0 | AN26: 0 | AO26: 0 | AP26: 0 | AQ26: 0 | AR26: 0 | AS26: 0 | AT26: 0 | AU26: 0 | AV26: 0 | AW26: 0 | AX26: 0
A27: Reductions — Professional services ($K) | C27: 0 | D27: 0 | E27: 0 | F27: 0 | G27: 30 | H27: 60 | I27: 90 | J27: 120 | K27: 150 | L27: 180 | M27: 210 | N27: 240 | O27: 270 | P27: 300 | Q27: 330 | R27: 360 | S27: 390 | T27: 420 | U27: 450 | V27: 480 | W27: 510 | X27: 540 | Y27: 570 | Z27: 600 | AA27: 630 | AB27: 660 | AC27: 690 | AD27: 720 | AE27: 720 | AF27: 720 | AG27: 720 | AH27: 720 | AI27: 720 | AJ27: 720 | AK27: 720 | AL27: 720 | AM27: 720 | AN27: 720 | AO27: 720 | AP27: 720 | AQ27: 720 | AR27: 720 | AS27: 720 | AT27: 720 | AU27: 720 | AV27: 720 | AW27: 720 | AX27: 720
A28: Reductions — Offshore contractors ($K) | C28: 0 | D28: 0 | E28: 0 | F28: 0 | G28: 0 | H28: 0 | I28: 0 | J28: 12 | K28: 24 | L28: 36 | M28: 48 | N28: 60 | O28: 72 | P28: 84 | Q28: 96 | R28: 108 | S28: 120 | T28: 132 | U28: 144 | V28: 156 | W28: 168 | X28: 180 | Y28: 192 | Z28: 204 | AA28: 216 | AB28: 228 | AC28: 240 | AD28: 252 | AE28: 264 | AF28: 276 | AG28: 288 | AH28: 300 | AI28: 300 | AJ28: 300 | AK28: 300 | AL28: 300 | AM28: 300 | AN28: 300 | AO28: 300 | AP28: 300 | AQ28: 300 | AR28: 300 | AS28: 300 | AT28: 300 | AU28: 300 | AV28: 300 | AW28: 300 | AX28: 300
A29: Reductions — Onshore contractors ($K) | C29: 0 | D29: 0 | E29: 0 | F29: 0 | G29: 0 | H29: 0 | I29: 0 | J29: 10 | K29: 19 | L29: 29 | M29: 38 | N29: 48 | O29: 58 | P29: 67 | Q29: 77 | R29: 86 | S29: 96 | T29: 106 | U29: 115 | V29: 125 | W29: 134 | X29: 144 | Y29: 154 | Z29: 163 | AA29: 173 | AB29: 182 | AC29: 192 | AD29: 202 | AE29: 211 | AF29: 221 | AG29: 230 | AH29: 240 | AI29: 240 | AJ29: 240 | AK29: 240 | AL29: 240 | AM29: 240 | AN29: 240 | AO29: 240 | AP29: 240 | AQ29: 240 | AR29: 240 | AS29: 240 | AT29: 240 | AU29: 240 | AV29: 240 | AW29: 240 | AX29: 240
A30: Reductions — Employees / Other ($K) | C30: 0 | D30: 0 | E30: 0 | F30: 0 | G30: 0 | H30: 0 | I30: 0 | J30: 0 | K30: 0 | L30: 0 | M30: 5 | N30: 10 | O30: 14 | P30: 19 | Q30: 24 | R30: 29 | S30: 34 | T30: 38 | U30: 43 | V30: 48 | W30: 53 | X30: 58 | Y30: 62 | Z30: 67 | AA30: 72 | AB30: 77 | AC30: 82 | AD30: 86 | AE30: 91 | AF30: 96 | AG30: 101 | AH30: 106 | AI30: 110 | AJ30: 115 | AK30: 120 | AL30: 120 | AM30: 120 | AN30: 120 | AO30: 120 | AP30: 120 | AQ30: 120 | AR30: 120 | AS30: 120 | AT30: 120 | AU30: 120 | AV30: 120 | AW30: 120 | AX30: 120
A31: India cost adds ($K) | C31: 26 | D31: 52 | E31: 79 | F31: 105 | G31: 131 | H31: 158 | I31: 184 | J31: 210 | K31: 236 | L31: 262 | M31: 289 | N31: 315 | O31: 360 | P31: 405 | Q31: 450 | R31: 495 | S31: 540 | T31: 585 | U31: 630 | V31: 675 | W31: 720 | X31: 765 | Y31: 810 | Z31: 855 | AA31: 855 | AB31: 855 | AC31: 855 | AD31: 855 | AE31: 855 | AF31: 855 | AG31: 855 | AH31: 855 | AI31: 855 | AJ31: 855 | AK31: 855 | AL31: 855 | AM31: 855 | AN31: 855 | AO31: 855 | AP31: 855 | AQ31: 855 | AR31: 855 | AS31: 855 | AT31: 855 | AU31: 855 | AV31: 855 | AW31: 855 | AX31: 855
A32: Net labor arbitrage ($K) | C32: =SUM(C27:C30)-C31 | D32: =SUM(D27:D30)-D31 | E32: =SUM(E27:E30)-E31 | F32: =SUM(F27:F30)-F31 | G32: =SUM(G27:G30)-G31 | H32: =SUM(H27:H30)-H31 | I32: =SUM(I27:I30)-I31 | J32: =SUM(J27:J30)-J31 | ... AX32: =SUM(AX27:AX30)-AX31
A34: =CONCATENATE("ORG: ",Setup!$B$7)
A35: India hires (heads) | C35: 7 | D35: 7 | E35: 7 | F35: 7 | G35: 7 | H35: 7 | I35: 7 | J35: 7 | K35: 7 | L35: 7 | M35: 7 | N35: 7 | O35: 11 | P35: 11 | Q35: 11 | R35: 11 | S35: 11 | T35: 11 | U35: 11 | V35: 11 | W35: 11 | X35: 11 | Y35: 11 | Z35: 11 | AA35: 0 | AB35: 0 | AC35: 0 | AD35: 0 | AE35: 0 | AF35: 0 | AG35: 0 | AH35: 0 | AI35: 0 | AJ35: 0 | AK35: 0 | AL35: 0 | AM35: 0 | AN35: 0 | AO35: 0 | AP35: 0 | AQ35: 0 | AR35: 0 | AS35: 0 | AT35: 0 | AU35: 0 | AV35: 0 | AW35: 0 | AX35: 0
A36: Reductions — Professional services ($K) | C36: 0 | D36: 0 | E36: 0 | F36: 0 | G36: 28 | H36: 55 | I36: 82 | J36: 110 | K36: 138 | L36: 165 | M36: 193 | N36: 220 | O36: 248 | P36: 275 | Q36: 302 | R36: 330 | S36: 358 | T36: 385 | U36: 413 | V36: 440 | W36: 468 | X36: 495 | Y36: 522 | Z36: 550 | AA36: 578 | AB36: 605 | AC36: 632 | AD36: 660 | AE36: 660 | AF36: 660 | AG36: 660 | AH36: 660 | AI36: 660 | AJ36: 660 | AK36: 660 | AL36: 660 | AM36: 660 | AN36: 660 | AO36: 660 | AP36: 660 | AQ36: 660 | AR36: 660 | AS36: 660 | AT36: 660 | AU36: 660 | AV36: 660 | AW36: 660 | AX36: 660
A37: Reductions — Offshore contractors ($K) | C37: 0 | D37: 0 | E37: 0 | F37: 0 | G37: 0 | H37: 0 | I37: 0 | J37: 11 | K37: 22 | L37: 33 | M37: 44 | N37: 55 | O37: 66 | P37: 77 | Q37: 88 | R37: 99 | S37: 110 | T37: 121 | U37: 132 | V37: 143 | W37: 154 | X37: 165 | Y37: 176 | Z37: 187 | AA37: 198 | AB37: 209 | AC37: 220 | AD37: 231 | AE37: 242 | AF37: 253 | AG37: 264 | AH37: 275 | AI37: 275 | AJ37: 275 | AK37: 275 | AL37: 275 | AM37: 275 | AN37: 275 | AO37: 275 | AP37: 275 | AQ37: 275 | AR37: 275 | AS37: 275 | AT37: 275 | AU37: 275 | AV37: 275 | AW37: 275 | AX37: 275
A38: Reductions — Onshore contractors ($K) | C38: 0 | D38: 0 | E38: 0 | F38: 0 | G38: 0 | H38: 0 | I38: 0 | J38: 9 | K38: 18 | L38: 26 | M38: 35 | N38: 44 | O38: 53 | P38: 62 | Q38: 70 | R38: 79 | S38: 88 | T38: 97 | U38: 106 | V38: 114 | W38: 123 | X38: 132 | Y38: 141 | Z38: 150 | AA38: 158 | AB38: 167 | AC38: 176 | AD38: 185 | AE38: 194 | AF38: 202 | AG38: 211 | AH38: 220 | AI38: 220 | AJ38: 220 | AK38: 220 | AL38: 220 | AM38: 220 | AN38: 220 | AO38: 220 | AP38: 220 | AQ38: 220 | AR38: 220 | AS38: 220 | AT38: 220 | AU38: 220 | AV38: 220 | AW38: 220 | AX38: 220
A39: Reductions — Employees / Other ($K) | C39: 0 | D39: 0 | E39: 0 | F39: 0 | G39: 0 | H39: 0 | I39: 0 | J39: 0 | K39: 0 | L39: 0 | M39: 4 | N39: 9 | O39: 13 | P39: 18 | Q39: 22 | R39: 26 | S39: 31 | T39: 35 | U39: 40 | V39: 44 | W39: 48 | X39: 53 | Y39: 57 | Z39: 62 | AA39: 66 | AB39: 70 | AC39: 75 | AD39: 79 | AE39: 84 | AF39: 88 | AG39: 92 | AH39: 97 | AI39: 101 | AJ39: 106 | AK39: 110 | AL39: 110 | AM39: 110 | AN39: 110 | AO39: 110 | AP39: 110 | AQ39: 110 | AR39: 110 | AS39: 110 | AT39: 110 | AU39: 110 | AV39: 110 | AW39: 110 | AX39: 110
A40: India cost adds ($K) | C40: 26 | D40: 52 | E40: 79 | F40: 105 | G40: 131 | H40: 158 | I40: 184 | J40: 210 | K40: 236 | L40: 262 | M40: 289 | N40: 315 | O40: 356 | P40: 398 | Q40: 439 | R40: 480 | S40: 521 | T40: 562 | U40: 604 | V40: 645 | W40: 686 | X40: 728 | Y40: 769 | Z40: 810 | AA40: 810 | AB40: 810 | AC40: 810 | AD40: 810 | AE40: 810 | AF40: 810 | AG40: 810 | AH40: 810 | AI40: 810 | AJ40: 810 | AK40: 810 | AL40: 810 | AM40: 810 | AN40: 810 | AO40: 810 | AP40: 810 | AQ40: 810 | AR40: 810 | AS40: 810 | AT40: 810 | AU40: 810 | AV40: 810 | AW40: 810 | AX40: 810
A41: Net labor arbitrage ($K) | C41: =SUM(C36:C39)-C40 | D41: =SUM(D36:D39)-D40 | E41: =SUM(E36:E39)-E40 | F41: =SUM(F36:F39)-F40 | G41: =SUM(G36:G39)-G40 | H41: =SUM(H36:H39)-H40 | I41: =SUM(I36:I39)-I40 | J41: =SUM(J36:J39)-J40 | ... AX41: =SUM(AX36:AX39)-AX40
A43: =CONCATENATE("ORG: ",Setup!$B$8)
A44: India hires (heads) | C44: 6 | D44: 6 | E44: 6 | F44: 6 | G44: 6 | H44: 6 | I44: 6 | J44: 6 | K44: 6 | L44: 6 | M44: 6 | N44: 6 | O44: 10 | P44: 10 | Q44: 10 | R44: 10 | S44: 10 | T44: 10 | U44: 10 | V44: 10 | W44: 10 | X44: 10 | Y44: 10 | Z44: 10 | AA44: 0 | AB44: 0 | AC44: 0 | AD44: 0 | AE44: 0 | AF44: 0 | AG44: 0 | AH44: 0 | AI44: 0 | AJ44: 0 | AK44: 0 | AL44: 0 | AM44: 0 | AN44: 0 | AO44: 0 | AP44: 0 | AQ44: 0 | AR44: 0 | AS44: 0 | AT44: 0 | AU44: 0 | AV44: 0 | AW44: 0 | AX44: 0
A45: Reductions — Professional services ($K) | C45: 0 | D45: 0 | E45: 0 | F45: 0 | G45: 25 | H45: 50 | I45: 75 | J45: 100 | K45: 125 | L45: 150 | M45: 175 | N45: 200 | O45: 225 | P45: 250 | Q45: 275 | R45: 300 | S45: 325 | T45: 350 | U45: 375 | V45: 400 | W45: 425 | X45: 450 | Y45: 475 | Z45: 500 | AA45: 525 | AB45: 550 | AC45: 575 | AD45: 600 | AE45: 600 | AF45: 600 | AG45: 600 | AH45: 600 | AI45: 600 | AJ45: 600 | AK45: 600 | AL45: 600 | AM45: 600 | AN45: 600 | AO45: 600 | AP45: 600 | AQ45: 600 | AR45: 600 | AS45: 600 | AT45: 600 | AU45: 600 | AV45: 600 | AW45: 600 | AX45: 600
A46: Reductions — Offshore contractors ($K) | C46: 0 | D46: 0 | E46: 0 | F46: 0 | G46: 0 | H46: 0 | I46: 0 | J46: 10 | K46: 20 | L46: 30 | M46: 40 | N46: 50 | O46: 60 | P46: 70 | Q46: 80 | R46: 90 | S46: 100 | T46: 110 | U46: 120 | V46: 130 | W46: 140 | X46: 150 | Y46: 160 | Z46: 170 | AA46: 180 | AB46: 190 | AC46: 200 | AD46: 210 | AE46: 220 | AF46: 230 | AG46: 240 | AH46: 250 | AI46: 250 | AJ46: 250 | AK46: 250 | AL46: 250 | AM46: 250 | AN46: 250 | AO46: 250 | AP46: 250 | AQ46: 250 | AR46: 250 | AS46: 250 | AT46: 250 | AU46: 250 | AV46: 250 | AW46: 250 | AX46: 250
...

Sheet Org_1
A1: =CONCATENATE("ORG: ",Setup!$B$4)
A2: Enter BLUE cells only. GREEN = central fill. GREY = linked target (do not edit). See READ ME + Guiding Principles tabs.
C4: 2026 | O4: 2027 | AA4: 2028 | AM4: 2029
A5: Metric | B5: Unit / who fills | C5: 46023 | D5: 46054 | E5: 46082 | F5: 46113 | G5: 46143 | H5: 46174 | I5: 46204 | J5: 46235 | K5: 46266 | L5: 46296 | M5: 46327 | N5: 46357 | O5: 46388 | P5: 46419 | Q5: 46447 | R5: 46478 | S5: 46508 | T5: 46539 | U5: 46569 | V5: 46600 | W5: 46631 | X5: 46661 | Y5: 46692 | Z5: 46722 | AA5: 46753 | AB5: 46784 | AC5: 46813 | AD5: 46844 | AE5: 46874 | AF5: 46905 | AG5: 46935 | AH5: 46966 | AI5: 46997 | AJ5: 47027 | AK5: 47058 | AL5: 47088 | AM5: 47119 | AN5: 47150 | AO5: 47178 | AP5: 47209 | AQ5: 47239 | AR5: 47270 | AS5: 47300 | AT5: 47331 | AU5: 47362 | AV5: 47392 | AW5: 47423 | AX5: 47453
A6: A. INDIA HIRING
A7: India hires — Target | B7: heads · linked | C7: =Targets!C8 | D7: =Targets!D8 | E7: =Targets!E8 | F7: =Targets!F8 | G7: =Targets!G8 | H7: =Targets!H8 | I7: =Targets!I8 | J7: =Targets!J8 | ... AX7: =Targets!AX8
A8: India hires — Actual | B8: heads · central (PlanIt) | C8: 5 | D8: 6 | E8: 6
A9: Cumulative hires — Target | B9: heads · auto | C9: =SUM($C7:C7) | D9: =SUM($C7:D7) | E9: =SUM($C7:E7) | F9: =SUM($C7:F7) | G9: =SUM($C7:G7) | H9: =SUM($C7:H7) | I9: =SUM($C7:I7) | J9: =SUM($C7:J7) | ... AX9: =SUM($C7:AX7)
A10: Cumulative hires — Actual | B10: heads · auto | C10: =SUM($C8:C8) | D10: =SUM($C8:D8) | E10: =SUM($C8:E8) | F10: =SUM($C8:F8) | G10: =SUM($C8:G8) | H10: =SUM($C8:H8) | I10: =SUM($C8:I8) | J10: =SUM($C8:J8) | ... AX10: =SUM($C8:AX8)
A11: Hires variance (Actual − Target), cumulative | B11: heads · auto | C11: =C10-C9 | D11: =D10-D9 | E11: =E10-E9 | F11: =F10-F9 | G11: =G10-G9 | H11: =H10-H9 | I11: =I10-I9 | J11: =J10-J9 | ... AX11: =AX10-AX9
A12: Avg India loaded comp — Plan | B12: $K/yr · central (PlanIt) | C12: 45 | D12: 45 | E12: 45
A13: Avg India loaded comp — Actual | B13: $K/yr · central (PlanIt) | C13: 44 | D13: 46 | E13: 47
A14: India attrition in month | B14: heads · central (HR) | C14: 0 | D14: 0 | E14: 1
A15: % of India hires fully productive | B15: % · org input | C15: 0 | D15: 0.2 | E15: 0.4
A16: B. GROSS REDUCTIONS REALIZED IN PERIOD
A17: Professional services — Target | B17: $K · linked | C17: =Targets!C9 | D17: =Targets!D9 | E17: =Targets!E9 | F17: =Targets!F9 | G17: =Targets!G9 | H17: =Targets!H9 | I17: =Targets!I9 | J17: =Targets!J9 | ... AX17: =Targets!AX9
A18: Professional services — Actual | B18: $K · org input | C18: 0 | D18: 20 | E18: 45
A19: Offshore contractors — Target | B19: $K · linked | C19: =Targets!C10 | D19: =Targets!D10 | E19: =Targets!E10 | F19: =Targets!F10 | G19: =Targets!G10 | H19: =Targets!H10 | I19: =Targets!I10 | J19: =Targets!J10 | ... AX19: =Targets!AX10
A20: Offshore contractors — Actual | B20: $K · org input | C20: 0 | D20: 0 | E20: 10
A21: Onshore contractors — Target | B21: $K · linked | C21: =Targets!C11 | D21: =Targets!D11 | E21: =Targets!E11 | F21: =Targets!F11 | G21: =Targets!G11 | H21: =Targets!H11 | I21: =Targets!I11 | J21: =Targets!J11 | ... AX21: =Targets!AX11
A22: Onshore contractors — Actual | B22: $K · org input | C22: 0 | D22: 0 | E22: 5
A23: Employees / Other — Target | B23: $K · linked | C23: =Targets!C12 | D23: =Targets!D12 | E23: =Targets!E12 | F23: =Targets!F12 | G23: =Targets!G12 | H23: =Targets!H12 | I23: =Targets!I12 | J23: =Targets!J12 | ... AX23: =Targets!AX12
A24: Employees / Other — Actual | B24: $K · org input | C24: 0 | D24: 0 | E24: 0
A25: Total gross reductions — Target | B25: $K · auto | C25: =C17+C19+C21+C23 | D25: =D17+D19+D21+D23 | E25: =E17+E19+E21+E23 | F25: =F17+F19+F21+F23 | G25: =G17+G19+G21+G23 | H25: =H17+H19+H21+H23 | I25: =I17+I19+I21+I23 | J25: =J17+J19+J21+J23 | ... AX25: =AX17+AX19+AX21+AX23
A26: Total gross reductions — Actual | B26: $K · auto | C26: =C18+C20+C22+C24 | D26: =D18+D20+D22+D24 | E26: =E18+E20+E22+E24 | F26: =F18+F20+F22+F24 | G26: =G18+G20+G22+G24 | H26: =H18+H20+H22+H24 | I26: =I18+I20+I22+I24 | J26: =J18+J20+J22+J24 | ... AX26: =AX18+AX20+AX22+AX24
A27: Gross reductions variance | B27: $K · auto | C27: =C26-C25 | D27: =D26-D25 | E27: =E26-E25 | F27: =F26-F25 | G27: =G26-G25 | H27: =H26-H25 | I27: =I26-I25 | J27: =J26-J25 | ... AX27: =AX26-AX25
A28: Headcount reduced in month — Actual | B28: heads · org input | C28: 0 | D28: 1 | E28: 3
A29: Exit run-rate of reductions (annualized) | B29: $K · org input | C29: 0 | D29: 240 | E29: 720
A30: C. INDIA COST ADDS
A31: India loaded cost adds — Target | B31: $K · linked | C31: =Targets!C13 | D31: =Targets!D13 | E31: =Targets!E13 | F31: =Targets!F13 | G31: =Targets!G13 | H31: =Targets!H13 | I31: =Targets!I13 | J31: =Targets!J13 | ... AX31: =Targets!AX13
A32: India loaded cost adds — Actual | B32: $K · org input | C32: 19 | D32: 41 | E32: 64
A33: One-time transition costs (memo — never net) | B33: $K · org input | C33: 35 | D33: 15 | E33: 10
A34: D. NET LABOR ARBITRAGE (B − C)
A35: Net labor arbitrage — Target | B35: $K · linked | C35: =Targets!C14 | D35: =Targets!D14 | E35: =Targets!E14 | F35: =Targets!F14 | G35: =Targets!G14 | H35: =Targets!H14 | I35: =Targets!I14 | J35: =Targets!J14 | ... AX35: =Targets!AX14
A36: Net labor arbitrage — Actual | B36: $K · auto | C36: =C26-C32 | D36: =D26-D32 | E36: =E26-E32 | F36: =F26-F32 | G36: =G26-G32 | H36: =H26-H32 | I36: =I26-I32 | J36: =J26-J32 | ... AX36: =AX26-AX32
A37: Net variance (Actual − Target) | B37: $K · auto | C37: =C36-C35 | D37: =D36-D35 | E37: =E36-E35 | F37: =F36-F35 | G37: =G36-G35 | H37: =H36-H35 | I37: =I36-I35 | J37: =J36-J35 | ... AX37: =AX36-AX35
A38: Cumulative net arbitrage — Target | B38: $K · auto | C38: =SUM($C35:C35) | D38: =SUM($C35:D35) | E38: =SUM($C35:E35) | F38: =SUM($C35:F35) | G38: =SUM($C35:G35) | H38: =SUM($C35:H35) | I38: =SUM($C35:I35) | J38: =SUM($C35:J35) | ... AX38: =SUM($C35:AX35)
A39: Cumulative net arbitrage — Actual | B39: $K · auto | C39: =SUM($C36:C36) | D39: =SUM($C36:D36) | E39: =SUM($C36:E36) | F39: =SUM($C36:F36) | G39: =SUM($C36:G36) | H39: =SUM($C36:H36) | I39: =SUM($C36:I36) | J39: =SUM($C36:J36) | ... AX39: =SUM($C36:AX36)
A40: E. STATUS, ATTESTATION & COMMENTARY
A41: Overall RAG status for month | B41: G/A/R · org input | C41: Green | D41: Green | E41: Amber
...

Sheet Org_2
A1: =CONCATENATE("ORG: ",Setup!$B$5)
A2: Enter BLUE cells only. GREEN = central fill. GREY = linked target (do not edit). See READ ME + Guiding Principles tabs.
C4: 2026 | O4: 2027 | AA4: 2028 | AM4: 2029
A5: Metric | B5: Unit / who fills | C5: 46023 | D5: 46054 | E5: 46082 | F5: 46113 | G5: 46143 | H5: 46174 | I5: 46204 | J5: 46235 | K5: 46266 | L5: 46296 | M5: 46327 | N5: 46357 | O5: 46388 | P5: 46419 | Q5: 46447 | R5: 46478 | S5: 46508 | T5: 46539 | U5: 46569 | V5: 46600 | W5: 46631 | X5: 46661 | Y5: 46692 | Z5: 46722 | AA5: 46753 | AB5: 46784 | AC5: 46813 | AD5: 46844 | AE5: 46874 | AF5: 46905 | AG5: 46935 | AH5: 46966 | AI5: 46997 | AJ5: 47027 | AK5: 47058 | AL5: 47088 | AM5: 47119 | AN5: 47150 | AO5: 47178 | AP5: 47209 | AQ5: 47239 | AR5: 47270 | AS5: 47300 | AT5: 47331 | AU5: 47362 | AV5: 47392 | AW5: 47423 | AX5: 47453
A6: A. INDIA HIRING
A7: India hires — Target | B7: heads · linked | C7: =Targets!C17 | D7: =Targets!D17 | E7: =Targets!E17 | F7: =Targets!F17 | G7: =Targets!G17 | H7: =Targets!H17 | I7: =Targets!I17 | J7: =Targets!J17 | ... AX7: =Targets!AX17
A8: India hires — Actual | B8: heads · central (PlanIt)
A9: Cumulative hires — Target | B9: heads · auto | C9: =SUM($C7:C7) | D9: =SUM($C7:D7) | E9: =SUM($C7:E7) | F9: =SUM($C7:F7) | G9: =SUM($C7:G7) | H9: =SUM($C7:H7) | I9: =SUM($C7:I7) | J9: =SUM($C7:J7) | ... AX9: =SUM($C7:AX7)
A10: Cumulative hires — Actual | B10: heads · auto | C10: =SUM($C8:C8) | D10: =SUM($C8:D8) | E10: =SUM($C8:E8) | F10: =SUM($C8:F8) | G10: =SUM($C8:G8) | H10: =SUM($C8:H8) | I10: =SUM($C8:I8) | J10: =SUM($C8:J8) | ... AX10: =SUM($C8:AX8)
A11: Hires variance (Actual − Target), cumulative | B11: heads · auto | C11: =C10-C9 | D11: =D10-D9 | E11: =E10-E9 | F11: =F10-F9 | G11: =G10-G9 | H11: =H10-H9 | I11: =I10-I9 | J11: =J10-J9 | ... AX11: =AX10-AX9
A12: Avg India loaded comp — Plan | B12: $K/yr · central (PlanIt)
A13: Avg India loaded comp — Actual | B13: $K/yr · central (PlanIt)
A14: India attrition in month | B14: heads · central (HR)
A15: % of India hires fully productive | B15: % · org input
A16: B. GROSS REDUCTIONS REALIZED IN PERIOD
A17: Professional services — Target | B17: $K · linked | C17: =Targets!C18 | D17: =Targets!D18 | E17: =Targets!E18 | F17: =Targets!F18 | G17: =Targets!G18 | H17: =Targets!H18 | I17: =Targets!I18 | J17: =Targets!J18 | ... AX17: =Targets!AX18
A18: Professional services — Actual | B18: $K · org input
A19: Offshore contractors — Target | B19: $K · linked | C19: =Targets!C19 | D19: =Targets!D19 | E19: =Targets!E19 | F19: =Targets!F19 | G19: =Targets!G19 | H19: =Targets!H19 | I19: =Targets!I19 | J19: =Targets!J19 | ... AX19: =Targets!AX19
A20: Offshore contractors — Actual | B20: $K · org input
A21: Onshore contractors — Target | B21: $K · linked | C21: =Targets!C20 | D21: =Targets!D20 | E21: =Targets!E20 | F21: =Targets!F20 | G21: =Targets!G20 | H21: =Targets!H20 | I21: =Targets!I20 | J21: =Targets!J20 | ... AX21: =Targets!AX20
A22: Onshore contractors — Actual | B22: $K · org input
A23: Employees / Other — Target | B23: $K · linked | C23: =Targets!C21 | D23: =Targets!D21 | E23: =Targets!E21 | F23: =Targets!F21 | G23: =Targets!G21 | H23: =Targets!H21 | I23: =Targets!I21 | J23: =Targets!J21 | ... AX23: =Targets!AX21
A24: Employees / Other — Actual | B24: $K · org input
A25: Total gross reductions — Target | B25: $K · auto | C25: =C17+C19+C21+C23 | D25: =D17+D19+D21+D23 | E25: =E17+E19+E21+E23 | F25: =F17+F19+F21+F23 | G25: =G17+G19+G21+G23 | H25: =H17+H19+H21+H23 | I25: =I17+I19+I21+I23 | J25: =J17+J19+J21+J23 | ... AX25: =AX17+AX19+AX21+AX23
A26: Total gross reductions — Actual | B26: $K · auto | C26: =C18+C20+C22+C24 | D26: =D18+D20+D22+D24 | E26: =E18+E20+E22+E24 | F26: =F18+F20+F22+F24 | G26: =G18+G20+G22+G24 | H26: =H18+H20+H22+H24 | I26: =I18+I20+I22+I24 | J26: =J18+J20+J22+J24 | ... AX26: =AX18+AX20+AX22+AX24
A27: Gross reductions variance | B27: $K · auto | C27: =C26-C25 | D27: =D26-D25 | E27: =E26-E25 | F27: =F26-F25 | G27: =G26-G25 | H27: =H26-H25 | I27: =I26-I25 | J27: =J26-J25 | ... AX27: =AX26-AX25
A28: Headcount reduced in month — Actual | B28: heads · org input
A29: Exit run-rate of reductions (annualized) | B29: $K · org input
A30: C. INDIA COST ADDS
A31: India loaded cost adds — Target | B31: $K · linked | C31: =Targets!C22 | D31: =Targets!D22 | E31: =Targets!E22 | F31: =Targets!F22 | G31: =Targets!G22 | H31: =Targets!H22 | I31: =Targets!I22 | J31: =Targets!J22 | ... AX31: =Targets!AX22
A32: India loaded cost adds — Actual | B32: $K · org input
A33: One-time transition costs (memo — never net) | B33: $K · org input
A34: D. NET LABOR ARBITRAGE (B − C)
A35: Net labor arbitrage — Target | B35: $K · linked | C35: =Targets!C23 | D35: =Targets!D23 | E35: =Targets!E23 | F35: =Targets!F23 | G35: =Targets!G23 | H35: =Targets!H23 | I35: =Targets!I23 | J35: =Targets!J23 | ... AX35: =Targets!AX23
A36: Net labor arbitrage — Actual | B36: $K · auto | C36: =C26-C32 | D36: =D26-D32 | E36: =E26-E32 | F36: =F26-F32 | G36: =G26-G32 | H36: =H26-H32 | I36: =I26-I32 | J36: =J26-J32 | ... AX36: =AX26-AX32
A37: Net variance (Actual − Target) | B37: $K · auto | C37: =C36-C35 | D37: =D36-D35 | E37: =E36-E35 | F37: =F36-F35 | G37: =G36-G35 | H37: =H36-H35 | I37: =I36-I35 | J37: =J36-J35 | ... AX37: =AX36-AX35
A38: Cumulative net arbitrage — Target | B38: $K · auto | C38: =SUM($C35:C35) | D38: =SUM($C35:D35) | E38: =SUM($C35:E35) | F38: =SUM($C35:F35) | G38: =SUM($C35:G35) | H38: =SUM($C35:H35) | I38: =SUM($C35:I35) | J38: =SUM($C35:J35) | ... AX38: =SUM($C35:AX35)
A39: Cumulative net arbitrage — Actual | B39: $K · auto | C39: =SUM($C36:C36) | D39: =SUM($C36:D36) | E39: =SUM($C36:E36) | F39: =SUM($C36:F36) | G39: =SUM($C36:G36) | H39: =SUM($C36:H36) | I39: =SUM($C36:I36) | J39: =SUM($C36:J36) | ... AX39: =SUM($C36:AX36)
A40: E. STATUS, ATTESTATION & COMMENTARY
A41: Overall RAG status for month | B41: G/A/R · org input
...

Sheet Org_3
A1: =CONCATENATE("ORG: ",Setup!$B$6)
A2: Enter BLUE cells only. GREEN = central fill. GREY = linked target (do not edit). See READ ME + Guiding Principles tabs.
C4: 2026 | O4: 2027 | AA4: 2028 | AM4: 2029
A5: Metric | B5: Unit / who fills | C5: 46023 | D5: 46054 | E5: 46082 | F5: 46113 | G5: 46143 | H5: 46174 | I5: 46204 | J5: 46235 | K5: 46266 | L5: 46296 | M5: 46327 | N5: 46357 | O5: 46388 | P5: 46419 | Q5: 46447 | R5: 46478 | S5: 46508 | T5: 46539 | U5: 46569 | V5: 46600 | W5: 46631 | X5: 46661 | Y5: 46692 | Z5: 46722 | AA5: 46753 | AB5: 46784 | AC5: 46813 | AD5: 46844 | AE5: 46874 | AF5: 46905 | AG5: 46935 | AH5: 46966 | AI5: 46997 | AJ5: 47027 | AK5: 47058 | AL5: 47088 | AM5: 47119 | AN5: 47150 | AO5: 47178 | AP5: 47209 | AQ5: 47239 | AR5: 47270 | AS5: 47300 | AT5: 47331 | AU5: 47362 | AV5: 47392 | AW5: 47423 | AX5: 47453
A6: A. INDIA HIRING
A7: India hires — Target | B7: heads · linked | C7: =Targets!C26 | D7: =Targets!D26 | E7: =Targets!E26 | F7: =Targets!F26 | G7: =Targets!G26 | H7: =Targets!H26 | I7: =Targets!I26 | J7: =Targets!J26 | ... AX7: =Targets!AX26
A8: India hires — Actual | B8: heads · central (PlanIt)
A9: Cumulative hires — Target | B9: heads · auto | C9: =SUM($C7:C7) | D9: =SUM($C7:D7) | E9: =SUM($C7:E7) | F9: =SUM($C7:F7) | G9: =SUM($C7:G7) | H9: =SUM($C7:H7) | I9: =SUM($C7:I7) | J9: =SUM($C7:J7) | ... AX9: =SUM($C7:AX7)
A10: Cumulative hires — Actual | B10: heads · auto | C10: =SUM($C8:C8) | D10: =SUM($C8:D8) | E10: =SUM($C8:E8) | F10: =SUM($C8:F8) | G10: =SUM($C8:G8) | H10: =SUM($C8:H8) | I10: =SUM($C8:I8) | J10: =SUM($C8:J8) | ... AX10: =SUM($C8:AX8)
A11: Hires variance (Actual − Target), cumulative | B11: heads · auto | C11: =C10-C9 | D11: =D10-D9 | E11: =E10-E9 | F11: =F10-F9 | G11: =G10-G9 | H11: =H10-H9 | I11: =I10-I9 | J11: =J10-J9 | ... AX11: =AX10-AX9
A12: Avg India loaded comp — Plan | B12: $K/yr · central (PlanIt)
A13: Avg India loaded comp — Actual | B13: $K/yr · central (PlanIt)
A14: India attrition in month | B14: heads · central (HR)
A15: % of India hires fully productive | B15: % · org input
A16: B. GROSS REDUCTIONS REALIZED IN PERIOD
A17: Professional services — Target | B17: $K · linked | C17: =Targets!C27 | D17: =Targets!D27 | E17: =Targets!E27 | F17: =Targets!F27 | G17: =Targets!G27 | H17: =Targets!H27 | I17: =Targets!I27 | J17: =Targets!J27 | ... AX17: =Targets!AX27
A18: Professional services — Actual | B18: $K · org input
A19: Offshore contractors — Target | B19: $K · linked | C19: =Targets!C28 | D19: =Targets!D28 | E19: =Targets!E28 | F19: =Targets!F28 | G19: =Targets!G28 | H19: =Targets!H28 | I19: =Targets!I28 | J19: =Targets!J28 | ... AX19: =Targets!AX28
A20: Offshore contractors — Actual | B20: $K · org input
A21: Onshore contractors — Target | B21: $K · linked | C21: =Targets!C29 | D21: =Targets!D29 | E21: =Targets!E29 | F21: =Targets!F29 | G21: =Targets!G29 | H21: =Targets!H29 | I21: =Targets!I29 | J21: =Targets!J29 | ... AX21: =Targets!AX29
A22: Onshore contractors — Actual | B22: $K · org input
A23: Employees / Other — Target | B23: $K · linked | C23: =Targets!C30 | D23: =Targets!D30 | E23: =Targets!E30 | F23: =Targets!F30 | G23: =Targets!G30 | H23: =Targets!H30 | I23: =Targets!I30 | J23: =Targets!J30 | ... AX23: =Targets!AX30
A24: Employees / Other — Actual | B24: $K · org input
A25: Total gross reductions — Target | B25: $K · auto | C25: =C17+C19+C21+C23 | D25: =D17+D19+D21+D23 | E25: =E17+E19+E21+E23 | F25: =F17+F19+F21+F23 | G25: =G17+G19+G21+G23 | H25: =H17+H19+H21+H23 | I25: =I17+I19+I21+I23 | J25: =J17+J19+J21+J23 | ... AX25: =AX17+AX19+AX21+AX23
A26: Total gross reductions — Actual | B26: $K · auto | C26: =C18+C20+C22+C24 | D26: =D18+D20+D22+D24 | E26: =E18+E20+E22+E24 | F26: =F18+F20+F22+F24 | G26: =G18+G20+G22+G24 | H26: =H18+H20+H22+H24 | I26: =I18+I20+I22+I24 | J26: =J18+J20+J22+J24 | ... AX26: =AX18+AX20+AX22+AX24
A27: Gross reductions variance | B27: $K · auto | C27: =C26-C25 | D27: =D26-D25 | E27: =E26-E25 | F27: =F26-F25 | G27: =G26-G25 | H27: =H26-H25 | I27: =I26-I25 | J27: =J26-J25 | ... AX27: =AX26-AX25
A28: Headcount reduced in month — Actual | B28: heads · org input
A29: Exit run-rate of reductions (annualized) | B29: $K · org input
A30: C. INDIA COST ADDS
A31: India loaded cost adds — Target | B31: $K · linked | C31: =Targets!C31 | D31: =Targets!D31 | E31: =Targets!E31 | F31: =Targets!F31 | G31: =Targets!G31 | H31: =Targets!H31 | I31: =Targets!I31 | J31: =Targets!J31 | ... AX31: =Targets!AX31
A32: India loaded cost adds — Actual | B32: $K · org input
A33: One-time transition costs (memo — never net) | B33: $K · org input
A34: D. NET LABOR ARBITRAGE (B − C)
A35: Net labor arbitrage — Target | B35: $K · linked | C35: =Targets!C32 | D35: =Targets!D32 | E35: =Targets!E32 | F35: =Targets!F32 | G35: =Targets!G32 | H35: =Targets!H32 | I35: =Targets!I32 | J35: =Targets!J32 | ... AX35: =Targets!AX32
A36: Net labor arbitrage — Actual | B36: $K · auto | C36: =C26-C32 | D36: =D26-D32 | E36: =E26-E32 | F36: =F26-F32 | G36: =G26-G32 | H36: =H26-H32 | I36: =I26-I32 | J36: =J26-J32 | ... AX36: =AX26-AX32
A37: Net variance (Actual − Target) | B37: $K · auto | C37: =C36-C35 | D37: =D36-D35 | E37: =E36-E35 | F37: =F36-F35 | G37: =G36-G35 | H37: =H36-H35 | I37: =I36-I35 | J37: =J36-J35 | ... AX37: =AX36-AX35
A38: Cumulative net arbitrage — Target | B38: $K · auto | C38: =SUM($C35:C35) | D38: =SUM($C35:D35) | E38: =SUM($C35:E35) | F38: =SUM($C35:F35) | G38: =SUM($C35:G35) | H38: =SUM($C35:H35) | I38: =SUM($C35:I35) | J38: =SUM($C35:J35) | ... AX38: =SUM($C35:AX35)
A39: Cumulative net arbitrage — Actual | B39: $K · auto | C39: =SUM($C36:C36) | D39: =SUM($C36:D36) | E39: =SUM($C36:E36) | F39: =SUM($C36:F36) | G39: =SUM($C36:G36) | H39: =SUM($C36:H36) | I39: =SUM($C36:I36) | J39: =SUM($C36:J36) | ... AX39: =SUM($C36:AX36)
A40: E. STATUS, ATTESTATION & COMMENTARY
A41: Overall RAG status for month | B41: G/A/R · org input
...

Sheet Org_4
A1: =CONCATENATE("ORG: ",Setup!$B$7)
A2: Enter BLUE cells only. GREEN = central fill. GREY = linked target (do not edit). See READ ME + Guiding Principles tabs.
C4: 2026 | O4: 2027 | AA4: 2028 | AM4: 2029
A5: Metric | B5: Unit / who fills | C5: 46023 | D5: 46054 | E5: 46082 | F5: 46113 | G5: 46143 | H5: 46174 | I5: 46204 | J5: 46235 | K5: 46266 | L5: 46296 | M5: 46327 | N5: 46357 | O5: 46388 | P5: 46419 | Q5: 46447 | R5: 46478 | S5: 46508 | T5: 46539 | U5: 46569 | V5: 46600 | W5: 46631 | X5: 46661 | Y5: 46692 | Z5: 46722 | AA5: 46753 | AB5: 46784 | AC5: 46813 | AD5: 46844 | AE5: 46874 | AF5: 46905 | AG5: 46935 | AH5: 46966 | AI5: 46997 | AJ5: 47027 | AK5: 47058 | AL5: 47088 | AM5: 47119 | AN5: 47150 | AO5: 47178 | AP5: 47209 | AQ5: 47239 | AR5: 47270 | AS5: 47300 | AT5: 47331 | AU5: 47362 | AV5: 47392 | AW5: 47423 | AX5: 47453
A6: A. INDIA HIRING
A7: India hires — Target | B7: heads · linked | C7: =Targets!C35 | D7: =Targets!D35 | E7: =Targets!E35 | F7: =Targets!F35 | G7: =Targets!G35 | H7: =Targets!H35 | I7: =Targets!I35 | J7: =Targets!J35 | ... AX7: =Targets!AX35
A8: India hires — Actual | B8: heads · central (PlanIt)
A9: Cumulative hires — Target | B9: heads · auto | C9: =SUM($C7:C7) | D9: =SUM($C7:D7) | E9: =SUM($C7:E7) | F9: =SUM($C7:F7) | G9: =SUM($C7:G7) | H9: =SUM($C7:H7) | I9: =SUM($C7:I7) | J9: =SUM($C7:J7) | ... AX9: =SUM($C7:AX7)
A10: Cumulative hires — Actual | B10: heads · auto | C10: =SUM($C8:C8) | D10: =SUM($C8:D8) | E10: =SUM($C8:E8) | F10: =SUM($C8:F8) | G10: =SUM($C8:G8) | H10: =SUM($C8:H8) | I10: =SUM($C8:I8) | J10: =SUM($C8:J8) | ... AX10: =SUM($C8:AX8)
A11: Hires variance (Actual − Target), cumulative | B11: heads · auto | C11: =C10-C9 | D11: =D10-D9 | E11: =E10-E9 | F11: =F10-F9 | G11: =G10-G9 | H11: =H10-H9 | I11: =I10-I9 | J11: =J10-J9 | ... AX11: =AX10-AX9
A12: Avg India loaded comp — Plan | B12: $K/yr · central (PlanIt)
A13: Avg India loaded comp — Actual | B13: $K/yr · central (PlanIt)
A14: India attrition in month | B14: heads · central (HR)
A15: % of India hires fully productive | B15: % · org input
A16: B. GROSS REDUCTIONS REALIZED IN PERIOD
A17: Professional services — Target | B17: $K · linked | C17: =Targets!C36 | D17: =Targets!D36 | E17: =Targets!E36 | F17: =Targets!F36 | G17: =Targets!G36 | H17: =Targets!H36 | I17: =Targets!I36 | J17: =Targets!J36 | ... AX17: =Targets!AX36
A18: Professional services — Actual | B18: $K · org input
A19: Offshore contractors — Target | B19: $K · linked | C19: =Targets!C37 | D19: =Targets!D37 | E19: =Targets!E37 | F19: =Targets!F37 | G19: =Targets!G37 | H19: =Targets!H37 | I19: =Targets!I37 | J19: =Targets!J37 | ... AX19: =Targets!AX37
A20: Offshore contractors — Actual | B20: $K · org input
A21: Onshore contractors — Target | B21: $K · linked | C21: =Targets!C38 | D21: =Targets!D38 | E21: =Targets!E38 | F21: =Targets!F38 | G21: =Targets!G38 | H21: =Targets!H38 | I21: =Targets!I38 | J21: =Targets!J38 | ... AX21: =Targets!AX38
A22: Onshore contractors — Actual | B22: $K · org input
A23: Employees / Other — Target | B23: $K · linked | C23: =Targets!C39 | D23: =Targets!D39 | E23: =Targets!E39 | F23: =Targets!F39 | G23: =Targets!G39 | H23: =Targets!H39 | I23: =Targets!I39 | J23: =Targets!J39 | ... AX23: =Targets!AX39
A24: Employees / Other — Actual | B24: $K · org input
A25: Total gross reductions — Target | B25: $K · auto | C25: =C17+C19+C21+C23 | D25: =D17+D19+D21+D23 | E25: =E17+E19+E21+E23 | F25: =F17+F19+F21+F23 | G25: =G17+G19+G21+G23 | H25: =H17+H19+H21+H23 | I25: =I17+I19+I21+I23 | J25: =J17+J19+J21+J23 | ... AX25: =AX17+AX19+AX21+AX23
A26: Total gross reductions — Actual | B26: $K · auto | C26: =C18+C20+C22+C24 | D26: =D18+D20+D22+D24 | E26: =E18+E20+E22+E24 | F26: =F18+F20+F22+F24 | G26: =G18+G20+G22+G24 | H26: =H18+H20+H22+H24 | I26: =I18+I20+I22+I24 | J26: =J18+J20+J22+J24 | ... AX26: =AX18+AX20+AX22+AX24
A27: Gross reductions variance | B27: $K · auto | C27: =C26-C25 | D27: =D26-D25 | E27: =E26-E25 | F27: =F26-F25 | G27: =G26-G25 | H27: =H26-H25 | I27: =I26-I25 | J27: =J26-J25 | ... AX27: =AX26-AX25
A28: Headcount reduced in month — Actual | B28: heads · org input
A29: Exit run-rate of reductions (annualized) | B29: $K · org input
A30: C. INDIA COST ADDS
A31: India loaded cost adds — Target | B31: $K · linked | C31: =Targets!C40 | D31: =Targets!D40 | E31: =Targets!E40 | F31: =Targets!F40 | G31: =Targets!G40 | H31: =Targets!H40 | I31: =Targets!I40 | J31: =Targets!J40 | ... AX31: =Targets!AX40
A32: India loaded cost adds — Actual | B32: $K · org input
A33: One-time transition costs (memo — never net) | B33: $K · org input
A34: D. NET LABOR ARBITRAGE (B − C)
A35: Net labor arbitrage — Target | B35: $K · linked | C35: =Targets!C41 | D35: =Targets!D41 | E35: =Targets!E41 | F35: =Targets!F41 | G35: =Targets!G41 | H35: =Targets!H41 | I35: =Targets!I41 | J35: =Targets!J41 | ... AX35: =Targets!AX41
A36: Net labor arbitrage — Actual | B36: $K · auto | C36: =C26-C32 | D36: =D26-D32 | E36: =E26-E32 | F36: =F26-F32 | G36: =G26-G32 | H36: =H26-H32 | I36: =I26-I32 | J36: =J26-J32 | ... AX36: =AX26-AX32
A37: Net variance (Actual − Target) | B37: $K · auto | C37: =C36-C35 | D37: =D36-D35 | E37: =E36-E35 | F37: =F36-F35 | G37: =G36-G35 | H37: =H36-H35 | I37: =I36-I35 | J37: =J36-J35 | ... AX37: =AX36-AX35
A38: Cumulative net arbitrage — Target | B38: $K · auto | C38: =SUM($C35:C35) | D38: =SUM($C35:D35) | E38: =SUM($C35:E35) | F38: =SUM($C35:F35) | G38: =SUM($C35:G35) | H38: =SUM($C35:H35) | I38: =SUM($C35:I35) | J38: =SUM($C35:J35) | ... AX38: =SUM($C35:AX35)
A39: Cumulative net arbitrage — Actual | B39: $K · auto | C39: =SUM($C36:C36) | D39: =SUM($C36:D36) | E39: =SUM($C36:E36) | F39: =SUM($C36:F36) | G39: =SUM($C36:G36) | H39: =SUM($C36:H36) | I39: =SUM($C36:I36) | J39: =SUM($C36:J36) | ... AX39: =SUM($C36:AX36)
A40: E. STATUS, ATTESTATION & COMMENTARY
A41: Overall RAG status for month | B41: G/A/R · org input
...

Sheet Org_5
A1: =CONCATENATE("ORG: ",Setup!$B$8)
A2: Enter BLUE cells only. GREEN = central fill. GREY = linked target (do not edit). See READ ME + Guiding Principles tabs.
C4: 2026 | O4: 2027 | AA4: 2028 | AM4: 2029
A5: Metric | B5: Unit / who fills | C5: 46023 | D5: 46054 | E5: 46082 | F5: 46113 | G5: 46143 | H5: 46174 | I5: 46204 | J5: 46235 | K5: 46266 | L5: 46296 | M5: 46327 | N5: 46357 | O5: 46388 | P5: 46419 | Q5: 46447 | R5: 46478 | S5: 46508 | T5: 46539 | U5: 46569 | V5: 46600 | W5: 46631 | X5: 46661 | Y5: 46692 | Z5: 46722 | AA5: 46753 | AB5: 46784 | AC5: 46813 | AD5: 46844 | AE5: 46874 | AF5: 46905 | AG5: 46935 | AH5: 46966 | AI5: 46997 | AJ5: 47027 | AK5: 47058 | AL5: 47088 | AM5: 47119 | AN5: 47150 | AO5: 47178 | AP5: 47209 | AQ5: 47239 | AR5: 47270 | AS5: 47300 | AT5: 47331 | AU5: 47362 | AV5: 47392 | AW5: 47423 | AX5: 47453
A6: A. INDIA HIRING
A7: India hires — Target | B7: heads · linked | C7: =Targets!C44 | D7: =Targets!D44 | E7: =Targets!E44 | F7: =Targets!F44 | G7: =Targets!G44 | H7: =Targets!H44 | I7: =Targets!I44 | J7: =Targets!J44 | ... AX7: =Targets!AX44
A8: India hires — Actual | B8: heads · central (PlanIt)
A9: Cumulative hires — Target | B9: heads · auto | C9: =SUM($C7:C7) | D9: =SUM($C7:D7) | E9: =SUM($C7:E7) | F9: =SUM($C7:F7) | G9: =SUM($C7:G7) | H9: =SUM($C7:H7) | I9: =SUM($C7:I7) | J9: =SUM($C7:J7) | ... AX9: =SUM($C7:AX7)
A10: Cumulative hires — Actual | B10: heads · auto | C10: =SUM($C8:C8) | D10: =SUM($C8:D8) | E10: =SUM($C8:E8) | F10: =SUM($C8:F8) | G10: =SUM($C8:G8) | H10: =SUM($C8:H8) | I10: =SUM($C8:I8) | J10: =SUM($C8:J8) | ... AX10: =SUM($C8:AX8)
A11: Hires variance (Actual − Target), cumulative | B11: heads · auto | C11: =C10-C9 | D11: =D10-D9 | E11: =E10-E9 | F11: =F10-F9 | G11: =G10-G9 | H11: =H10-H9 | I11: =I10-I9 | J11: =J10-J9 | ... AX11: =AX10-AX9
A12: Avg India loaded comp — Plan | B12: $K/yr · central (PlanIt)
A13: Avg India loaded comp — Actual | B13: $K/yr · central (PlanIt)
A14: India attrition in month | B14: heads · central (HR)
A15: % of India hires fully productive | B15: % · org input
A16: B. GROSS REDUCTIONS REALIZED IN PERIOD
A17: Professional services — Target | B17: $K · linked | C17: =Targets!C45 | D17: =Targets!D45 | E17: =Targets!E45 | F17: =Targets!F45 | G17: =Targets!G45 | H17: =Targets!H45 | I17: =Targets!I45 | J17: =Targets!J45 | ... AX17: =Targets!AX45
A18: Professional services — Actual | B18: $K · org input
A19: Offshore contractors — Target | B19: $K · linked | C19: =Targets!C46 | D19: =Targets!D46 | E19: =Targets!E46 | F19: =Targets!F46 | G19: =Targets!G46 | H19: =Targets!H46 | I19: =Targets!I46 | J19: =Targets!J46 | ... AX19: =Targets!AX46
A20: Offshore contractors — Actual | B20: $K · org input
A21: Onshore contractors — Target | B21: $K · linked | C21: =Targets!C47 | D21: =Targets!D47 | E21: =Targets!E47 | F21: =Targets!F47 | G21: =Targets!G47 | H21: =Targets!H47 | I21: =Targets!I47 | J21: =Targets!J47 | ... AX21: =Targets!AX47
A22: Onshore contractors — Actual | B22: $K · org input
A23: Employees / Other — Target | B23: $K · linked | C23: =Targets!C48 | D23: =Targets!D48 | E23: =Targets!E48 | F23: =Targets!F48 | G23: =Targets!G48 | H23: =Targets!H48 | I23: =Targets!I48 | J23: =Targets!J48 | ... AX23: =Targets!AX48
A24: Employees / Other — Actual | B24: $K · org input
A25: Total gross reductions — Target | B25: $K · auto | C25: =C17+C19+C21+C23 | D25: =D17+D19+D21+D23 | E25: =E17+E19+E21+E23 | F25: =F17+F19+F21+F23 | G25: =G17+G19+G21+G23 | H25: =H17+H19+H21+H23 | I25: =I17+I19+I21+I23 | J25: =J17+J19+J21+J23 | ... AX25: =AX17+AX19+AX21+AX23
A26: Total gross reductions — Actual | B26: $K · auto | C26: =C18+C20+C22+C24 | D26: =D18+D20+D22+D24 | E26: =E18+E20+E22+E24 | F26: =F18+F20+F22+F24 | G26: =G18+G20+G22+G24 | H26: =H18+H20+H22+H24 | I26: =I18+I20+I22+I24 | J26: =J18+J20+J22+J24 | ... AX26: =AX18+AX20+AX22+AX24
A27: Gross reductions variance | B27: $K · auto | C27: =C26-C25 | D27: =D26-D25 | E27: =E26-E25 | F27: =F26-F25 | G27: =G26-G25 | H27: =H26-H25 | I27: =I26-I25 | J27: =J26-J25 | ... AX27: =AX26-AX25
A28: Headcount reduced in month — Actual | B28: heads · org input
A29: Exit run-rate of reductions (annualized) | B29: $K · org input
A30: C. INDIA COST ADDS
A31: India loaded cost adds — Target | B31: $K · linked | C31: =Targets!C49 | D31: =Targets!D49 | E31: =Targets!E49 | F31: =Targets!F49 | G31: =Targets!G49 | H31: =Targets!H49 | I31: =Targets!I49 | J31: =Targets!J49 | ... AX31: =Targets!AX49
A32: India loaded cost adds — Actual | B32: $K · org input
A33: One-time transition costs (memo — never net) | B33: $K · org input
A34: D. NET LABOR ARBITRAGE (B − C)
A35: Net labor arbitrage — Target | B35: $K · linked | C35: =Targets!C50 | D35: =Targets!D50 | E35: =Targets!E50 | F35: =Targets!F50 | G35: =Targets!G50 | H35: =Targets!H50 | I35: =Targets!I50 | J35: =Targets!J50 | ... AX35: =Targets!AX50
A36: Net labor arbitrage — Actual | B36: $K · auto | C36: =C26-C32 | D36: =D26-D32 | E36: =E26-E32 | F36: =F26-F32 | G36: =G26-G32 | H36: =H26-H32 | I36: =I26-I32 | J36: =J26-J32 | ... AX36: =AX26-AX32
A37: Net variance (Actual − Target) | B37: $K · auto | C37: =C36-C35 | D37: =D36-D35 | E37: =E36-E35 | F37: =F36-F35 | G37: =G36-G35 | H37: =H36-H35 | I37: =I36-I35 | J37: =J36-J35 | ... AX37: =AX36-AX35
A38: Cumulative net arbitrage — Target | B38: $K · auto | C38: =SUM($C35:C35) | D38: =SUM($C35:D35) | E38: =SUM($C35:E35) | F38: =SUM($C35:F35) | G38: =SUM($C35:G35) | H38: =SUM($C35:H35) | I38: =SUM($C35:I35) | J38: =SUM($C35:J35) | ... AX38: =SUM($C35:AX35)
A39: Cumulative net arbitrage — Actual | B39: $K · auto | C39: =SUM($C36:C36) | D39: =SUM($C36:D36) | E39: =SUM($C36:E36) | F39: =SUM($C36:F36) | G39: =SUM($C36:G36) | H39: =SUM($C36:H36) | I39: =SUM($C36:I36) | J39: =SUM($C36:J36) | ... AX39: =SUM($C36:AX36)
A40: E. STATUS, ATTESTATION & COMMENTARY
A41: Overall RAG status for month | B41: G/A/R · org input
...

Sheet Org_6
A1: =CONCATENATE("ORG: ",Setup!$B$9)
A2: Enter BLUE cells only. GREEN = central fill. GREY = linked target (do not edit). See READ ME + Guiding Principles tabs.
C4: 2026 | O4: 2027 | AA4: 2028 | AM4: 2029
A5: Metric | B5: Unit / who fills | C5: 46023 | D5: 46054 | E5: 46082 | F5: 46113 | G5: 46143 | H5: 46174 | I5: 46204 | J5: 46235 | K5: 46266 | L5: 46296 | M5: 46327 | N5: 46357 | O5: 46388 | P5: 46419 | Q5: 46447 | R5: 46478 | S5: 46508 | T5: 46539 | U5: 46569 | V5: 46600 | W5: 46631 | X5: 46661 | Y5: 46692 | Z5: 46722 | AA5: 46753 | AB5: 46784 | AC5: 46813 | AD5: 46844 | AE5: 46874 | AF5: 46905 | AG5: 46935 | AH5: 46966 | AI5: 46997 | AJ5: 47027 | AK5: 47058 | AL5: 47088 | AM5: 47119 | AN5: 47150 | AO5: 47178 | AP5: 47209 | AQ5: 47239 | AR5: 47270 | AS5: 47300 | AT5: 47331 | AU5: 47362 | AV5: 47392 | AW5: 47423 | AX5: 47453
A6: A. INDIA HIRING
A7: India hires — Target | B7: heads · linked | C7: =Targets!C53 | D7: =Targets!D53 | E7: =Targets!E53 | F7: =Targets!F53 | G7: =Targets!G53 | H7: =Targets!H53 | I7: =Targets!I53 | J7: =Targets!J53 | ... AX7: =Targets!AX53
A8: India hires — Actual | B8: heads · central (PlanIt)
A9: Cumulative hires — Target | B9: heads · auto | C9: =SUM($C7:C7) | D9: =SUM($C7:D7) | E9: =SUM($C7:E7) | F9: =SUM($C7:F7) | G9: =SUM($C7:G7) | H9: =SUM($C7:H7) | I9: =SUM($C7:I7) | J9: =SUM($C7:J7) | ... AX9: =SUM($C7:AX7)
A10: Cumulative hires — Actual | B10: heads · auto | C10: =SUM($C8:C8) | D10: =SUM($C8:D8) | E10: =SUM($C8:E8) | F10: =SUM($C8:F8) | G10: =SUM($C8:G8) | H10: =SUM($C8:H8) | I10: =SUM($C8:I8) | J10: =SUM($C8:J8) | ... AX10: =SUM($C8:AX8)
A11: Hires variance (Actual − Target), cumulative | B11: heads · auto | C11: =C10-C9 | D11: =D10-D9 | E11: =E10-E9 | F11: =F10-F9 | G11: =G10-G9 | H11: =H10-H9 | I11: =I10-I9 | J11: =J10-J9 | ... AX11: =AX10-AX9
A12: Avg India loaded comp — Plan | B12: $K/yr · central (PlanIt)
A13: Avg India loaded comp — Actual | B13: $K/yr · central (PlanIt)
A14: India attrition in month | B14: heads · central (HR)
A15: % of India hires fully productive | B15: % · org input
A16: B. GROSS REDUCTIONS REALIZED IN PERIOD
A17: Professional services — Target | B17: $K · linked | C17: =Targets!C54 | D17: =Targets!D54 | E17: =Targets!E54 | F17: =Targets!F54 | G17: =Targets!G54 | H17: =Targets!H54 | I17: =Targets!I54 | J17: =Targets!J54 | ... AX17: =Targets!AX54
A18: Professional services — Actual | B18: $K · org input
A19: Offshore contractors — Target | B19: $K · linked | C19: =Targets!C55 | D19: =Targets!D55 | E19: =Targets!E55 | F19: =Targets!F55 | G19: =Targets!G55 | H19: =Targets!H55 | I19: =Targets!I55 | J19: =Targets!J55 | ... AX19: =Targets!AX55
A20: Offshore contractors — Actual | B20: $K · org input
A21: Onshore contractors — Target | B21: $K · linked | C21: =Targets!C56 | D21: =Targets!D56 | E21: =Targets!E56 | F21: =Targets!F56 | G21: =Targets!G56 | H21: =Targets!H56 | I21: =Targets!I56 | J21: =Targets!J56 | ... AX21: =Targets!AX56
A22: Onshore contractors — Actual | B22: $K · org input
A23: Employees / Other — Target | B23: $K · linked | C23: =Targets!C57 | D23: =Targets!D57 | E23: =Targets!E57 | F23: =Targets!F57 | G23: =Targets!G57 | H23: =Targets!H57 | I23: =Targets!I57 | J23: =Targets!J57 | ... AX23: =Targets!AX57
A24: Employees / Other — Actual | B24: $K · org input
A25: Total gross reductions — Target | B25: $K · auto | C25: =C17+C19+C21+C23 | D25: =D17+D19+D21+D23 | E25: =E17+E19+E21+E23 | F25: =F17+F19+F21+F23 | G25: =G17+G19+G21+G23 | H25: =H17+H19+H21+H23 | I25: =I17+I19+I21+I23 | J25: =J17+J19+J21+J23 | ... AX25: =AX17+AX19+AX21+AX23
A26: Total gross reductions — Actual | B26: $K · auto | C26: =C18+C20+C22+C24 | D26: =D18+D20+D22+D24 | E26: =E18+E20+E22+E24 | F26: =F18+F20+F22+F24 | G26: =G18+G20+G22+G24 | H26: =H18+H20+H22+H24 | I26: =I18+I20+I22+I24 | J26: =J18+J20+J22+J24 | ... AX26: =AX18+AX20+AX22+AX24
A27: Gross reductions variance | B27: $K · auto | C27: =C26-C25 | D27: =D26-D25 | E27: =E26-E25 | F27: =F26-F25 | G27: =G26-G25 | H27: =H26-H25 | I27: =I26-I25 | J27: =J26-J25 | ... AX27: =AX26-AX25
A28: Headcount reduced in month — Actual | B28: heads · org input
A29: Exit run-rate of reductions (annualized) | B29: $K · org input
A30: C. INDIA COST ADDS
A31: India loaded cost adds — Target | B31: $K · linked | C31: =Targets!C58 | D31: =Targets!D58 | E31: =Targets!E58 | F31: =Targets!F58 | G31: =Targets!G58 | H31: =Targets!H58 | I31: =Targets!I58 | J31: =Targets!J58 | ... AX31: =Targets!AX58
A32: India loaded cost adds — Actual | B32: $K · org input
A33: One-time transition costs (memo — never net) | B33: $K · org input
A34: D. NET LABOR ARBITRAGE (B − C)
A35: Net labor arbitrage — Target | B35: $K · linked | C35: =Targets!C59 | D35: =Targets!D59 | E35: =Targets!E59 | F35: =Targets!F59 | G35: =Targets!G59 | H35: =Targets!H59 | I35: =Targets!I59 | J35: =Targets!J59 | ... AX35: =Targets!AX59
A36: Net labor arbitrage — Actual | B36: $K · auto | C36: =C26-C32 | D36: =D26-D32 | E36: =E26-E32 | F36: =F26-F32 | G36: =G26-G32 | H36: =H26-H32 | I36: =I26-I32 | J36: =J26-J32 | ... AX36: =AX26-AX32
A37: Net variance (Actual − Target) | B37: $K · auto | C37: =C36-C35 | D37: =D36-D35 | E37: =E36-E35 | F37: =F36-F35 | G37: =G36-G35 | H37: =H36-H35 | I37: =I36-I35 | J37: =J36-J35 | ... AX37: =AX36-AX35
A38: Cumulative net arbitrage — Target | B38: $K · auto | C38: =SUM($C35:C35) | D38: =SUM($C35:D35) | E38: =SUM($C35:E35) | F38: =SUM($C35:F35) | G38: =SUM($C35:G35) | H38: =SUM($C35:H35) | I38: =SUM($C35:I35) | J38: =SUM($C35:J35) | ... AX38: =SUM($C35:AX35)
A39: Cumulative net arbitrage — Actual | B39: $K · auto | C39: =SUM($C36:C36) | D39: =SUM($C36:D36) | E39: =SUM($C36:E36) | F39: =SUM($C36:F36) | G39: =SUM($C36:G36) | H39: =SUM($C36:H36) | I39: =SUM($C36:I36) | J39: =SUM($C36:J36) | ... AX39: =SUM($C36:AX36)
A40: E. STATUS, ATTESTATION & COMMENTARY
A41: Overall RAG status for month | B41: G/A/R · org input
...

Sheet Org_7
A1: =CONCATENATE("ORG: ",Setup!$B$10)
A2: Enter BLUE cells only. GREEN = central fill. GREY = linked target (do not edit). See READ ME + Guiding Principles tabs.
C4: 2026 | O4: 2027 | AA4: 2028 | AM4: 2029
A5: Metric | B5: Unit / who fills | C5: 46023 | D5: 46054 | E5: 46082 | F5: 46113 | G5: 46143 | H5: 46174 | I5: 46204 | J5: 46235 | K5: 46266 | L5: 46296 | M5: 46327 | N5: 46357 | O5: 46388 | P5: 46419 | Q5: 46447 | R5: 46478 | S5: 46508 | T5: 46539 | U5: 46569 | V5: 46600 | W5: 46631 | X5: 46661 | Y5: 46692 | Z5: 46722 | AA5: 46753 | AB5: 46784 | AC5: 46813 | AD5: 46844 | AE5: 46874 | AF5: 46905 | AG5: 46935 | AH5: 46966 | AI5: 46997 | AJ5: 47027 | AK5: 47058 | AL5: 47088 | AM5: 47119 | AN5: 47150 | AO5: 47178 | AP5: 47209 | AQ5: 47239 | AR5: 47270 | AS5: 47300 | AT5: 47331 | AU5: 47362 | AV5: 47392 | AW5: 47423 | AX5: 47453
A6: A. INDIA HIRING
A7: India hires — Target | B7: heads · linked | C7: =Targets!C62 | D7: =Targets!D62 | E7: =Targets!E62 | F7: =Targets!F62 | G7: =Targets!G62 | H7: =Targets!H62 | I7: =Targets!I62 | J7: =Targets!J62 | ... AX7: =Targets!AX62
A8: India hires — Actual | B8: heads · central (PlanIt)
A9: Cumulative hires — Target | B9: heads · auto | C9: =SUM($C7:C7) | D9: =SUM($C7:D7) | E9: =SUM($C7:E7) | F9: =SUM($C7:F7) | G9: =SUM($C7:G7) | H9: =SUM($C7:H7) | I9: =SUM($C7:I7) | J9: =SUM($C7:J7) | ... AX9: =SUM($C7:AX7)
A10: Cumulative hires — Actual | B10: heads · auto | C10: =SUM($C8:C8) | D10: =SUM($C8:D8) | E10: =SUM($C8:E8) | F10: =SUM($C8:F8) | G10: =SUM($C8:G8) | H10: =SUM($C8:H8) | I10: =SUM($C8:I8) | J10: =SUM($C8:J8) | ... AX10: =SUM($C8:AX8)
A11: Hires variance (Actual − Target), cumulative | B11: heads · auto | C11: =C10-C9 | D11: =D10-D9 | E11: =E10-E9 | F11: =F10-F9 | G11: =G10-G9 | H11: =H10-H9 | I11: =I10-I9 | J11: =J10-J9 | ... AX11: =AX10-AX9
A12: Avg India loaded comp — Plan | B12: $K/yr · central (PlanIt)
A13: Avg India loaded comp — Actual | B13: $K/yr · central (PlanIt)
A14: India attrition in month | B14: heads · central (HR)
A15: % of India hires fully productive | B15: % · org input
A16: B. GROSS REDUCTIONS REALIZED IN PERIOD
A17: Professional services — Target | B17: $K · linked | C17: =Targets!C63 | D17: =Targets!D63 | E17: =Targets!E63 | F17: =Targets!F63 | G17: =Targets!G63 | H17: =Targets!H63 | I17: =Targets!I63 | J17: =Targets!J63 | ... AX17: =Targets!AX63
A18: Professional services — Actual | B18: $K · org input
A19: Offshore contractors — Target | B19: $K · linked | C19: =Targets!C64 | D19: =Targets!D64 | E19: =Targets!E64 | F19: =Targets!F64 | G19: =Targets!G64 | H19: =Targets!H64 | I19: =Targets!I64 | J19: =Targets!J64 | ... AX19: =Targets!AX64
A20: Offshore contractors — Actual | B20: $K · org input
A21: Onshore contractors — Target | B21: $K · linked | C21: =Targets!C65 | D21: =Targets!D65 | E21: =Targets!E65 | F21: =Targets!F65 | G21: =Targets!G65 | H21: =Targets!H65 | I21: =Targets!I65 | J21: =Targets!J65 | ... AX21: =Targets!AX65
A22: Onshore contractors — Actual | B22: $K · org input
A23: Employees / Other — Target | B23: $K · linked | C23: =Targets!C66 | D23: =Targets!D66 | E23: =Targets!E66 | F23: =Targets!F66 | G23: =Targets!G66 | H23: =Targets!H66 | I23: =Targets!I66 | J23: =Targets!J66 | ... AX23: =Targets!AX66
A24: Employees / Other — Actual | B24: $K · org input
A25: Total gross reductions — Target | B25: $K · auto | C25: =C17+C19+C21+C23 | D25: =D17+D19+D21+D23 | E25: =E17+E19+E21+E23 | F25: =F17+F19+F21+F23 | G25: =G17+G19+G21+G23 | H25: =H17+H19+H21+H23 | I25: =I17+I19+I21+I23 | J25: =J17+J19+J21+J23 | ... AX25: =AX17+AX19+AX21+AX23
A26: Total gross reductions — Actual | B26: $K · auto | C26: =C18+C20+C22+C24 | D26: =D18+D20+D22+D24 | E26: =E18+E20+E22+E24 | F26: =F18+F20+F22+F24 | G26: =G18+G20+G22+G24 | H26: =H18+H20+H22+H24 | I26: =I18+I20+I22+I24 | J26: =J18+J20+J22+J24 | ... AX26: =AX18+AX20+AX22+AX24
A27: Gross reductions variance | B27: $K · auto | C27: =C26-C25 | D27: =D26-D25 | E27: =E26-E25 | F27: =F26-F25 | G27: =G26-G25 | H27: =H26-H25 | I27: =I26-I25 | J27: =J26-J25 | ... AX27: =AX26-AX25
A28: Headcount reduced in month — Actual | B28: heads · org input
A29: Exit run-rate of reductions (annualized) | B29: $K · org input
A30: C. INDIA COST ADDS
A31: India loaded cost adds — Target | B31: $K · linked | C31: =Targets!C67 | D31: =Targets!D67 | E31: =Targets!E67 | F31: =Targets!F67 | G31: =Targets!G67 | H31: =Targets!H67 | I31: =Targets!I67 | J31: =Targets!J67 | ... AX31: =Targets!AX67
A32: India loaded cost adds — Actual | B32: $K · org input
A33: One-time transition costs (memo — never net) | B33: $K · org input
A34: D. NET LABOR ARBITRAGE (B − C)
A35: Net labor arbitrage — Target | B35: $K · linked | C35: =Targets!C68 | D35: =Targets!D68 | E35: =Targets!E68 | F35: =Targets!F68 | G35: =Targets!G68 | H35: =Targets!H68 | I35: =Targets!I68 | J35: =Targets!J68 | ... AX35: =Targets!AX68
